Workbook
Name __xlnm.Print_Area_3: #REF!
Name __xlnm.Print_Titles_4: ('[1]LICENCES COMPETITION'!$A$1:$B$65536,'[1]LICENCES COMPETITION'!$A$1:$IV$2)
Name __xlnm.Print_Titles_5: ('[1]AUTRES LICENCES'!$A$1:$B$65536,'[1]AUTRES LICENCES'!$A$1:$IV$2)
Name _2009238A: #REF!
Name lic18: #REF!

Sheet Fusion
A2: Dep | B2: Code département | C2: Licxences | D2: Population départementale | E2: Part de Population départementale | F2: Revenu median
A3: 974 - La Réunion | B3: =TRIM(LEFT(A3,3)) -> 974 | C3: 173837 | D3: 892102 | E3: 0.19486225 | F3: =VLOOKUP(Tableau1[[#This Row],[Code département]],'Source 2'!A:C, 3, FALSE) -> 19110
A4: 93 - Seine-Saint-Denis | B4: =TRIM(LEFT(A4,3)) -> 93 | C4: 243240 | D4: 1702158 | E4: 0.14290095 | F4: =VLOOKUP(Tableau1[[#This Row],[Code département]],'Source 2'!A:C, 3, FALSE) -> 21250
A5: 11 - Aude | B5: =TRIM(LEFT(A5,3)) -> 11 | C5: 92766 | D5: 379190 | E5: 0.24464253 | F5: =VLOOKUP(Tableau1[[#This Row],[Code département]],'Source 2'!A:C, 3, FALSE) -> 23060
A6: 66 - Pyrénées-Orientales | B6: =TRIM(LEFT(A6,3)) -> 66 | C6: 128970 | D6: 500103 | E6: 0.25788688 | F6: =VLOOKUP(Tableau1[[#This Row],[Code département]],'Source 2'!A:C, 3, FALSE) -> 23080
A7: 23 - Creuse | B7: =TRIM(LEFT(A7,3)) -> 23 | C7: 29468 | D7: 114600 | E7: 0.25713787 | F7: =VLOOKUP(Tableau1[[#This Row],[Code département]],'Source 2'!A:C, 3, FALSE) -> 23210
A8: 62 - Pas-de-Calais | B8: =TRIM(LEFT(A8,3)) -> 62 | C8: 307191 | D8: 1453532 | E8: 0.21134106 | F8: =VLOOKUP(Tableau1[[#This Row],[Code département]],'Source 2'!A:C, 3, FALSE) -> 23260
A9: 02 - Aisne | B9: =TRIM(LEFT(A9,3)) -> 02 | C9: 103338 | D9: 521152 | E9: 0.19828764 | F9: =VLOOKUP(Tableau1[[#This Row],[Code département]],'Source 2'!A:C, 3, FALSE) -> 23360
A10: 09 - Ariège | B10: =TRIM(LEFT(A10,3)) -> 09 | C10: 45145 | D10: 156304 | E10: 0.28882818 | F10: =VLOOKUP(Tableau1[[#This Row],[Code département]],'Source 2'!A:C, 3, FALSE) -> 23360
A11: 08 - Ardennes | B11: =TRIM(LEFT(A11,3)) -> 08 | C11: 52676 | D11: 264556 | E11: 0.19911096 | F11: =VLOOKUP(Tableau1[[#This Row],[Code département]],'Source 2'!A:C, 3, FALSE) -> 23500
A12: 47 - Lot-et-Garonne | B12: =TRIM(LEFT(A12,3)) -> 47 | C12: 90157 | D12: 332318 | E12: 0.27129737 | F12: =VLOOKUP(Tableau1[[#This Row],[Code département]],'Source 2'!A:C, 3, FALSE) -> 23730
A13: 59 - Nord | B13: =TRIM(LEFT(A13,3)) -> 59 | C13: 618246 | D13: 2616167 | E13: 0.23631748 | F13: =VLOOKUP(Tableau1[[#This Row],[Code département]],'Source 2'!A:C, 3, FALSE) -> 23810
A14: 84 - Vaucluse | B14: =TRIM(LEFT(A14,3)) -> 84 | C14: 146557 | D14: 572065 | E14: 0.25618942 | F14: =VLOOKUP(Tableau1[[#This Row],[Code département]],'Source 2'!A:C, 3, FALSE) -> 23840
... A22: 2B - Haute-Corse | B22: =TRIM(LEFT(A22,3)) -> 2B | C22: 44402 | D22: 186724 | E22: 0.23779482 | F22: =VLOOKUP(Tableau1[[#This Row],[Code département]],'Source 2'!A:C, 3, FALSE) -> 24200
A23: 80 - Somme | B23: =TRIM(LEFT(A23,3)) -> 80 | C23: 132234 | D23: 561656 | E23: 0.23543593 | F23: =VLOOKUP(Tableau1[[#This Row],[Code département]],'Source 2'!A:C, 3, FALSE) -> 24200 | G23: Indicateurs (quanti x quanti) | H23: Valeur | I23: Lecture
A24: 04 - Alpes-de-Haute-Provence | B24: =TRIM(LEFT(A24,3)) -> 04 | C24: 45178 | D24: 168908 | E24: 0.26747105 | F24: =VLOOKUP(Tableau1[[#This Row],[Code département]],'Source 2'!A:C, 3, FALSE) -> 24240 | G24: Covariance | H24: =_xlfn.COVARIANCE.S(F3:F106,E3:E106) -> 9.6376503 | I24: Positive, les variables varient dans le même sens
A25: 48 - Lozère | B25: =TRIM(LEFT(A25,3)) -> 48 | C25: 27837 | D25: 76512 | E25: 0.36382528 | F25: =VLOOKUP(Tableau1[[#This Row],[Code département]],'Source 2'!A:C, 3, FALSE) -> 24270 | G25: Coefficient Pearson | H25: =CORREL(Tableau1[Revenu median],Tableau1[Part de Population départementale]) -> 0.12110207 | I25: Positive,Faible, quasi nulle
A26: 34 - Hérault | B26: =TRIM(LEFT(A26,3)) -> 34 | C26: 276608 | D26: 1241541 | E26: 0.22279409 | F26: =VLOOKUP(Tableau1[[#This Row],[Code département]],'Source 2'!A:C, 3, FALSE) -> 24280 | G26: Coeff de determina° (R²) | H26: =RSQ(E3:E106,F3:F106) -> 0.014665711 | I26: Revenu median explique 1,5% de la variation du taux de pratique
A27: 65 - Hautes-Pyrénées | B27: =TRIM(LEFT(A27,3)) -> 65 | C27: 64246 | D27: 232145 | E27: 0.27674945 | F27: =VLOOKUP(Tableau1[[#This Row],[Code département]],'Source 2'!A:C, 3, FALSE) -> 24320 | G27: Ordonnée (a) | H27: =INTERCEPT(E3:E106,F3:F106) -> 0.20192329
A28: 88 - Vosges | B28: =TRIM(LEFT(A28,3)) -> 88 | C28: 84429 | D28: 354450 | E28: 0.23819721 | F28: =VLOOKUP(Tableau1[[#This Row],[Code département]],'Source 2'!A:C, 3, FALSE) -> 24320 | G28: Pente | H28: =SLOPE(Tableau1[Part de Population départementale],Tableau1[Revenu median]) -> 2.2396689e-06 | I28: =H28*5000 -> 0.011198345 | J28: Pour 5000€ de revenu médian en plus, le taux de pratique sportive licenciée augmente ~ 1,1 point
A29: 82 - Tarn-et-Garonne | B29: =TRIM(LEFT(A29,3)) -> 82 | C29: 75013 | D29: 267035 | E29: 0.28091074 | F29: =VLOOKUP(Tableau1[[#This Row],[Code département]],'Source 2'!A:C, 3, FALSE) -> 24350
A30: 81 - Tarn | B30: =TRIM(LEFT(A30,3)) -> 81 | C30: 115502 | D30: 399634 | E30: 0.28901945 | F30: =VLOOKUP(Tableau1[[#This Row],[Code département]],'Source 2'!A:C, 3, FALSE) -> 24420
A31: 03 - Allier | B31: =TRIM(LEFT(A31,3)) -> 03 | C31: 82873 | D31: 333234 | E31: 0.24869311 | F31: =VLOOKUP(Tableau1[[#This Row],[Code département]],'Source 2'!A:C, 3, FALSE) -> 24430
A32: 89 - Yonne | B32: =TRIM(LEFT(A32,3)) -> 89 | C32: 71038 | D32: 331845 | E32: 0.21406982 | F32: =VLOOKUP(Tableau1[[#This Row],[Code département]],'Source 2'!A:C, 3, FALSE) -> 24590 | G32: RAPPORT DÉTAILLÉ (ToolPak)
A33: 18 - Cher | B33: =TRIM(LEFT(A33,3)) -> 18 | C33: 70288 | D33: 297019 | E33: 0.23664479 | F33: =VLOOKUP(Tableau1[[#This Row],[Code département]],'Source 2'!A:C, 3, FALSE) -> 24730
A34: 46 - Lot | B34: =TRIM(LEFT(A34,3)) -> 46 | C34: 50358 | D34: 176103 | E34: 0.28595765 | F34: =VLOOKUP(Tableau1[[#This Row],[Code département]],'Source 2'!A:C, 3, FALSE) -> 24740 | G34: Statistiques de la régression
A35: 55 - Meuse | B35: =TRIM(LEFT(A35,3)) -> 55 | C35: 47538 | D35: 178231 | E35: 0.26672128 | F35: =VLOOKUP(Tableau1[[#This Row],[Code département]],'Source 2'!A:C, 3, FALSE) -> 24740 | G35: Coefficient de détermination multiple | H35: 0.12110207
A36: 87 - Haute-Vienne | B36: =TRIM(LEFT(A36,3)) -> 87 | C36: 103192 | D36: 371847 | E36: 0.27751199 | F36: =VLOOKUP(Tableau1[[#This Row],[Code département]],'Source 2'!A:C, 3, FALSE) -> 24740 | G36: Coefficient de détermination R^2 | H36: 0.014665711
A37: 70 - Haute-Saône | B37: =TRIM(LEFT(A37,3)) -> 70 | C37: 51180 | D37: 232626 | E37: 0.2200098 | F37: =VLOOKUP(Tableau1[[#This Row],[Code département]],'Source 2'!A:C, 3, FALSE) -> 24750 | G37: Coefficient de détermination R^2 | H37: 0.004293771
A38: 32 - Gers | B38: =TRIM(LEFT(A38,3)) -> 32 | C38: 61357 | D38: 192920 | E38: 0.31804375 | F38: =VLOOKUP(Tableau1[[#This Row],[Code département]],'Source 2'!A:C, 3, FALSE) -> 24770 | G38: Erreur-type | H38: 0.038281729
A39: 12 - Aveyron | B39: =TRIM(LEFT(A39,3)) -> 12 | C39: 85755 | D39: 278821 | E39: 0.30756292 | F39: =VLOOKUP(Tableau1[[#This Row],[Code département]],'Source 2'!A:C, 3, FALSE) -> 24780 | G39: Observations | H39: 97
A40: 42 - Loire | B40: =TRIM(LEFT(A40,3)) -> 42 | C40: 197809 | D40: 775357 | E40: 0.2551199 | F40: =VLOOKUP(Tableau1[[#This Row],[Code département]],'Source 2'!A:C, 3, FALSE) -> 24800
A41: 07 - Ardèche | B41: =TRIM(LEFT(A41,3)) -> 07 | C41: 95765 | D41: 335833 | E41: 0.28515661 | F41: =VLOOKUP(Tableau1[[#This Row],[Code département]],'Source 2'!A:C, 3, FALSE) -> 24820 | G41: ANALYSE DE VARIANCE
A42: 15 - Cantal | B42: =TRIM(LEFT(A42,3)) -> 15 | C42: 40048 | D42: 143964 | E42: 0.27818066 | F42: =VLOOKUP(Tableau1[[#This Row],[Code département]],'Source 2'!A:C, 3, FALSE) -> 24820 | H42: Degré de liberté | I42: Somme des carrés | J42: Moyenne des carrés | K42: F | L42: Valeur critique de F
A43: 16 - Charente | B43: =TRIM(LEFT(A43,3)) -> 16 | C43: 83369 | D43: 350672 | E43: 0.23774068 | F43: =VLOOKUP(Tableau1[[#This Row],[Code département]],'Source 2'!A:C, 3, FALSE) -> 24850 | G43: Régression | H43: 1 | I43: 0.002072174 | J43: 0.002072174 | K43: 1.4139795 | L43: 0.23736061
A44: 19 - Corrèze | B44: =TRIM(LEFT(A44,3)) -> 19 | C44: 70883 | D44: 239704 | E44: 0.29571054 | F44: =VLOOKUP(Tableau1[[#This Row],[Code département]],'Source 2'!A:C, 3, FALSE) -> 24910 | G44: Résidus | H44: 95 | I44: 0.13922162 | J44: 0.0014654908
A45: 76 - Seine-Maritime | B45: =TRIM(LEFT(A45,3)) -> 76 | C45: 268363 | D45: 1260312 | E45: 0.21293378 | F45: =VLOOKUP(Tableau1[[#This Row],[Code département]],'Source 2'!A:C, 3, FALSE) -> 24940 | G45: Total | H45: 96 | I45: 0.1412938
A46: 86 - Vienne | B46: =TRIM(LEFT(A46,3)) -> 86 | C46: 117052 | D46: 437691 | E46: 0.26743068 | F46: =VLOOKUP(Tableau1[[#This Row],[Code département]],'Source 2'!A:C, 3, FALSE) -> 24940
A47: 71 - Saône-et-Loire | B47: =TRIM(LEFT(A47,3)) -> 71 | C47: 126486 | D47: 546754 | E47: 0.23133987 | F47: =VLOOKUP(Tableau1[[#This Row],[Code département]],'Source 2'!A:C, 3, FALSE) -> 24970 | H47: Coefficients | I47: Erreur-type | J47: Statistique t | K47: Probabilité | L47: Limite inférieure pour seuil de confiance = 95% | M47: Limite supérieure pour seuil de confiance = 95% | N47: Limite inférieure pour seuil de confiance = 95,0% | O47: Limite supérieure pour seuil de confiance = 95,0%
A48: 72 - Sarthe | B48: =TRIM(LEFT(A48,3)) -> 72 | C48: 151550 | D48: 564913 | E48: 0.2682714 | F48: =VLOOKUP(Tableau1[[#This Row],[Code département]],'Source 2'!A:C, 3, FALSE) -> 24990 | G48: Constante | H48: 0.20192329 | I48: 0.048157066 | J48: 4.1930148 | K48: 6.1774196e-05 | L48: 0.10631943 | M48: 0.29752715 | N48: 0.10631943 | O48: 0.29752715
...

Sheet Source 2
A1: Niveau de vie annuel médian en 2023
A3: en euros
A4: Code département | B4: Département | C4: Niveau de vie annuel médian
A5: 01 | B5: Ain | C5: 27990
A6: 02 | B6: Aisne | C6: 23360
A7: 03 | B7: Allier | C7: 24430
A8: 04 | B8: Alpes-de-Haute-Provence | C8: 24240
A9: 05 | B9: Hautes-Alpes | C9: 25060
A10: 06 | B10: Alpes-Maritimes | C10: 26380
A11: 07 | B11: Ardèche | C11: 24820
A12: 08 | B12: Ardennes | C12: 23500
A13: 09 | B13: Ariège | C13: 23360
A14: 10 | B14: Aube | C14: 24130
A15: 11 | B15: Aude | C15: 23060
A16: 12 | B16: Aveyron | C16: 24780
... A101: 974 | B101: La Réunion | C101: 19110
A102: Lecture : en 2023, dans l'Ain, la moitié de la population a un niveau de vie inférieur à 27 990 euros.
A103: Champ : France métropolitaine et La Réunion ; personnes appartenant à des ménages fiscaux vivant dans un logement ordinaire dont le revenu disponible est positif ou nul.
A104: Source : Insee-DGFiP-Cnaf-Cnav-CCMSA, Fichier localisé social et fiscal (Filosofi) 2023.

Sheet Source 1
A1: 5b. Licences annuelles par département pour la saison 2024 ou 2023/2024
A2: Données au 15/07/2025
A3: Source : Recensement des licences et clubs, INJEP-MEDES
A4: Groupe | B4: Code | C4: Fédération | D4: 01 - Ain | E4: 02 - Aisne | F4: 03 - Allier | G4: 04 - Alpes-de-Haute-Provence | H4: 05 - Hautes-Alpes | I4: 06 - Alpes-Maritimes | J4: 07 - Ardèche | K4: 08 - Ardennes | L4: 09 - Ariège | M4: 10 - Aube | N4: 11 - Aude | O4: 12 - Aveyron | P4: 13 - Bouches-du-Rhône | Q4: 14 - Calvados | R4: 15 - Cantal | S4: 16 - Charente | T4: 17 - Charente-Maritime | U4: 18 - Cher | V4: 19 - Corrèze | W4: 21 - Côte-d'Or | X4: 22 - Côtes-d'Armor | Y4: 23 - Creuse | Z4: 24 - Dordogne | AA4: 25 - Doubs | AB4: 26 - Drôme | AC4: 27 - Eure | AD4: 28 - Eure-et-Loir | AE4: 29 - Finistère | AF4: 2A - Corse-du-Sud | AG4: 2B - Haute-Corse | AH4: 30 - Gard | AI4: 31 - Haute-Garonne | AJ4: 32 - Gers | AK4: 33 - Gironde | AL4: 34 - Hérault | AM4: 35 - Ille-et-Vilaine | AN4: 36 - Indre | AO4: 37 - Indre-et-Loire | AP4: 38 - Isère | AQ4: 39 - Jura | AR4: 40 - Landes | AS4: 41 - Loir-et-Cher | AT4: 42 - Loire | AU4: 43 - Haute-Loire | AV4: 44 - Loire-Atlantique | AW4: 45 - Loiret | AX4: 46 - Lot | AY4: 47 - Lot-et-Garonne | AZ4: 48 - Lozère | BA4: 49 - Maine-et-Loire | BB4: 50 - Manche | BC4: 51 - Marne | BD4: 52 - Haute-Marne | BE4: 53 - Mayenne | BF4: 54 - Meurthe-et-Moselle | BG4: 55 - Meuse | BH4: 56 - Morbihan | BI4: 57 - Moselle | BJ4: 58 - Nièvre | BK4: 59 - Nord | BL4: 60 - Oise | BM4: 61 - Orne | BN4: 62 - Pas-de-Calais | BO4: 63 - Puy-de-Dôme | BP4: 64 - Pyrénées-Atlantiques | BQ4: 65 - Hautes-Pyrénées | BR4: 66 - Pyrénées-Orientales | BS4: 67 - Bas-Rhin | BT4: 68 - Haut-Rhin | BU4: 69 - Rhône | BV4: 70 - Haute-Saône | BW4: 71 - Saône-et-Loire | BX4: 72 - Sarthe | BY4: 73 - Savoie | BZ4: 74 - Haute-Savoie | CA4: 75 - Paris | CB4: 76 - Seine-Maritime | CC4: 77 - Seine-et-Marne | CD4: 78 - Yvelines | CE4: 79 - Deux-Sèvres | CF4: 80 - Somme | CG4: 81 - Tarn | CH4: 82 - Tarn-et-Garonne | CI4: 83 - Var | CJ4: 84 - Vaucluse | CK4: 85 - Vendée | CL4: 86 - Vienne | CM4: 87 - Haute-Vienne | CN4: 88 - Vosges | CO4: 89 - Yonne | CP4: 90 - Territoire de Belfort | CQ4: 91 - Essonne | CR4: 92 - Hauts-de-Seine | CS4: 93 - Seine-Saint-Denis | CT4: 94 - Val-de-Marne | CU4: 95 - Val-d'Oise | CV4: Total Métropole | CW4: 971 - Guadeloupe | CX4: 972 - Martinique | CY4: 973 - Guyane | CZ4: 974 - La Réunion | DA4: 976 - Mayotte | DB4: Total DROM | DC4: Total Métropole+DROM | DD4: 975 - St-Pierre-et-Miquelon | DE4: 977 - St-Barthélemy | DF4: 978 - St-Martin | DG4: 986 - Wallis-et-Futuna | DH4: 987 - Polynésie Française | DI4: 988 - Nouvelle-Calédonie | DJ4: Total COM | DK4: 980 - Monaco | DL4: Etranger | DM4: Non réparti | DN4: Total
A5: 1. Olympique(38) | D5: 108401 | E5: 66114 | F5: 46529 | G5: 24278 | H5: 27557 | I5: 175189 | J5: 50197 | K5: 34155 | L5: 24561 | M5: 37160 | N5: 51212 | O5: 40753 | P5: 288377 | Q5: 115366 | R5: 21348 | S5: 48806 | T5: 102192 | U5: 43406 | V5: 37124 | W5: 77398 | X5: 105693 | Y5: 14269 | Z5: 58929 | AA5: 78923 | AB5: 81417 | AC5: 91051 | AD5: 62842 | AE5: 152689 | AF5: 23902 | AG5: 25982 | AH5: 114510 | AI5: 236672 | AJ5: 34041 | AK5: 276744 | AL5: 172775 | AM5: 197604 | AN5: 31804 | AO5: 92192 | AP5: 204410 | AQ5: 40587 | AR5: 79823 | AS5: 50516 | AT5: 111782 | AU5: 36950 | AV5: 260945 | AW5: 104545 | AX5: 28094 | AY5: 51318 | AZ5: 10902 | BA5: 137906 | BB5: 81711 | BC5: 71028 | BD5: 23278 | BE5: 54642 | BF5: 99774 | BG5: 24611 | BH5: 134736 | BI5: 155219 | BJ5: 26629 | BK5: 346321 | BL5: 125071 | BM5: 34908 | BN5: 188776 | BO5: 103965 | BP5: 128736 | BQ5: 39317 | BR5: 67326 | BS5: 189165 | BT5: 115785 | BU5: 269437 | BV5: 30703 | BW5: 76008 | BX5: 82403 | BY5: 77789 | BZ5: 156570 | CA5: 205047 | CB5: 184703 | CC5: 206757 | CD5: 260463 | CE5: 57523 | CF5: 75394 | CG5: 60770 | CH5: 40467 | CI5: nd | CJ5: 82286 | CK5: 117566 | CL5: 68307 | CM5: 54758 | CN5: 50702 | CO5: 42235 | CP5: 18908 | CQ5: 198323 | CR5: 262302 | CS5: 146550 | CT5: 178775 | CU5: 168958 | CV5: 9744646 | CW5: 43111 | CX5: 38147 | CY5: 26894 | CZ5: 99617 | DA5: 25349 | DB5: 233118 | DC5: 9977764 | DD5: 2369 | DE5: 1365 | DF5: 3989 | DG5: 1277 | DH5: 6250 | DI5: 21776 | DJ5: 37026 | DK5: 7523 | DL5: 43313 | DM5: 0 | DN5: 10065626
B6: 111 | C6: Fédération Française de Football | D6: 25644 | E6: 21159 | F6: 14161 | G6: 4121 | H6: 2744 | I6: 28454 | J6: 11731 | K6: 11003 | L6: 4834 | M6: 9561 | N6: 10371 | O6: 12250 | P6: 53481 | Q6: 25370 | R6: 6525 | S6: 13221 | T6: 18216 | U6: 10685 | V6: 9102 | W6: 16144 | X6: 30330 | Y6: 4940 | Z6: 13896 | AA6: 24478 | AB6: 17160 | AC6: 20926 | AD6: 15954 | AE6: 41907 | AF6: 4969 | AG6: 6650 | AH6: 21903 | AI6: 45094 | AJ6: 6016 | AK6: 48986 | AL6: 34507 | AM6: 51943 | AN6: 10388 | AO6: 18869 | AP6: 43659 | AQ6: 10261 | AR6: 13373 | AS6: 12523 | AT6: 32139 | AU6: 11606 | AV6: 62427 | AW6: 21766 | AX6: 6218 | AY6: 9367 | AZ6: 3351 | BA6: 39101 | BB6: 18922 | BC6: 16534 | BD6: 7538 | BE6: 19623 | BF6: 25536 | BG6: 6349 | BH6: 34881 | BI6: 47867 | BJ6: 6436 | BK6: 104728 | BL6: 35046 | BM6: 10602 | BN6: 72696 | BO6: 23871 | BP6: 21607 | BQ6: 6962 | BR6: 11439 | BS6: 51192 | BT6: 31643 | BU6: 55726 | BV6: 9427 | BW6: 20046 | BX6: 24417 | BY6: 12233 | BZ6: 28754 | CA6: 25347 | CB6: 45080 | CC6: 49137 | CD6: 47185 | CE6: 18231 | CF6: 24056 | CG6: 12735 | CH6: 9637 | CI6: 27317 | CJ6: 16977 | CK6: 33655 | CL6: 18247 | CM6: 13002 | CN6: 12469 | CO6: 12158 | CP6: 5143 | CQ6: 43332 | CR6: 36506 | CS6: 45285 | CT6: 36429 | CU6: 44564 | CV6: 2274051 | CW6: 12925 | CX6: 10496 | CY6: 8599 | CZ6: 28009 | DA6: 15782 | DB6: 75811 | DC6: 2349862 | DD6: 809 | DE6: 9 | DF6: 1027 | DG6: 0 | DH6: 1 | DI6: 5 | DJ6: 1851 | DK6: 497 | DL6: 28 | DM6: 0 | DN6: 2352238
B7: 123 | C7: Fédération Française de Tennis | D7: 12492 | E7: 5440 | F7: 4361 | G7: 2742 | H7: 1935 | I7: 26906 | J7: 4786 | K7: 2360 | L7: 2557 | M7: 4175 | N7: 6092 | O7: 3011 | P7: 44424 | Q7: 10061 | R7: 1600 | S7: 4636 | T7: 10777 | U7: 3633 | V7: 2839 | W7: 6932 | X7: 8159 | Y7: 1194 | Z7: 6437 | AA7: 6179 | AB7: 9720 | AC7: 9230 | AD7: 7328 | AE7: 13120 | AF7: 2587 | AG7: 3090 | AH7: 14606 | AI7: 31559 | AJ7: 3578 | AK7: 37163 | AL7: 27923 | AM7: 16687 | AN7: 2469 | AO7: 10274 | AP7: 22716 | AQ7: 2613 | AR7: 9040 | AS7: 5864 | AT7: 11303 | AU7: 3688 | AV7: 25136 | AW7: 12364 | AX7: 2518 | AY7: 5377 | AZ7: 808 | BA7: 10579 | BB7: 7168 | BC7: 9525 | BD7: 2131 | BE7: 3277 | BF7: 9962 | BG7: 2690 | BH7: 10021 | BI7: 18602 | BJ7: 2584 | BK7: 37870 | BL7: 14467 | BM7: 3189 | BN7: 13566 | BO7: 10460 | BP7: 12687 | BQ7: 3491 | BR7: 10872 | BS7: 19382 | BT7: 11234 | BU7: 37950 | BV7: 1667 | BW7: 5774 | BX7: 5862 | BY7: 7656 | BZ7: 19428 | CA7: 47390 | CB7: 21085 | CC7: 25467 | CD7: 45536 | CE7: 4099 | CF7: 8241 | CG7: 6010 | CH7: 4031 | CI7: 23221 | CJ7: 10523 | CK7: 9006 | CL7: 6450 | CM7: 4857 | CN7: 5158 | CO7: 3926 | CP7: 1639 | CQ7: 26248 | CR7: 54240 | CS7: 17457 | CT7: 24595 | CU7: 22302 | CV7: 1138064 | CW7: 3719 | CX7: 3290 | CY7: 1463 | CZ7: 11432 | DA7: 250 | DB7: 20154 | DC7: 1158218 | DD7: 115 | DE7: 487 | DF7: 1150 | DG7: 58 | DH7: 10 | DI7: 2187 | DJ7: 4007 | DK7: 2793 | DL7: 4736 | DM7: 0 | DN7: 1169754
B8: 109 | C8: Fédération Française d'Équitation | D8: 8176 | E8: 5413 | F8: 3272 | G8: 1965 | H8: 1584 | I8: 6989 | J8: 3705 | K8: 2458 | L8: 1698 | M8: 2937 | N8: 3570 | O8: 3138 | P8: 15243 | Q8: 8366 | R8: 2021 | S8: 4240 | T8: 8352 | U8: 3623 | V8: 2482 | W8: 5745 | X8: 6922 | Y8: 1315 | Z8: 4856 | AA8: 5783 | AB8: 5419 | AC8: 8473 | AD8: 5257 | AE8: 8809 | AF8: 1293 | AG8: 1565 | AH8: 8638 | AI8: 14728 | AJ8: 2398 | AK8: 18238 | AL8: 11028 | AM8: 11314 | AN8: 2572 | AO8: 7850 | AP8: 12688 | AQ8: 3160 | AR8: 4601 | AS8: 3815 | AT8: 7533 | AU8: 2455 | AV8: 15654 | AW8: 6840 | AX8: 2228 | AY8: 3571 | AZ8: 1007 | BA8: 8800 | BB8: 7168 | BC8: 5645 | BD8: 1912 | BE8: 3027 | BF8: 7745 | BG8: 2306 | BH8: 8565 | BI8: 9848 | BJ8: 2053 | BK8: 23872 | BL8: 10609 | BM8: 3995 | BN8: 13913 | BO8: 6622 | BP8: 7379 | BQ8: 2584 | BR8: 4182 | BS8: 11572 | BT8: 6475 | BU8: 13317 | BV8: 2918 | BW8: 5759 | BX8: 5227 | BY8: 4209 | BZ8: 10147 | CA8: 11093 | CB8: 12952 | CC8: 14738 | CD8: 18230 | CE8: 4470 | CF8: 6913 | CG8: 4454 | CH8: 3052 | CI8: 9265 | CJ8: 4864 | CK8: 6842 | CL8: 4739 | CM8: 3753 | CN8: 3707 | CO8: 3477 | CP8: 1532 | CQ8: 11071 | CR8: 13483 | CS8: 3758 | CT8: 7211 | CU8: 8120 | CV8: 632560 | CW8: 1214 | CX8: 1185 | CY8: 664 | CZ8: 3008 | DA8: 25 | DB8: 6096 | DC8: 638656 | DD8: 58 | DE8: 10 | DF8: 31 | DG8: 0 | DH8: 433 | DI8: 1797 | DJ8: 2329 | DK8: 318 | DL8: 6951 | DM8: 0 | DN8: 648254
B9: 105 | C9: Fédération Française de Basketball | D9: 7362 | E9: 3448 | F9: 2710 | G9: 748 | H9: 659 | I9: 8060 | J9: 3077 | K9: 1760 | L9: 1295 | M9: 1507 | N9: 1433 | O9: 2486 | P9: 12915 | Q9: 7654 | R9: 548 | S9: 2520 | T9: 5109 | U9: 2241 | V9: 1660 | W9: 4549 | X9: 5099 | Y9: 1339 | Z9: 3158 | AA9: 2393 | AB9: 4625 | AC9: 5019 | AD9: 3627 | AE9: 7981 | AF9: 647 | AG9: 842 | AH9: 4315 | AI9: 13328 | AJ9: 2739 | AK9: 13241 | AL9: 6994 | AM9: 16980 | AN9: 2028 | AO9: 6835 | AP9: 12775 | AQ9: 1829 | AR9: 9309 | AS9: 2871 | AT9: 14415 | AU9: 2313 | AV9: 27167 | AW9: 8232 | AX9: 1074 | AY9: 5475 | AZ9: 125 | BA9: 18720 | BB9: 3108 | BC9: 4205 | BD9: 482 | BE9: 3950 | BF9: 6061 | BG9: 1244 | BH9: 8703 | BI9: 5821 | BJ9: 1370 | BK9: 29784 | BL9: 6716 | BM9: 1564 | BN9: 16209 | BO9: 8115 | BP9: 7994 | BQ9: 2331 | BR9: 3170 | BS9: 15548 | BT9: 7626 | BU9: 20075 | BV9: 1296 | BW9: 5400 | BX9: 8433 | BY9: 3206 | BZ9: 5713 | CA9: 7229 | CB9: 11932 | CC9: 11638 | CD9: 13317 | CE9: 3579 | CF9: 2997 | CG9: 3222 | CH9: 2115 | CI9: 6276 | CJ9: 3470 | CK9: 13097 | CL9: 3702 | CM9: 5074 | CN9: 2445 | CO9: 1964 | CP9: 668 | CQ9: 11734 | CR9: 10538 | CS9: 8149 | CT9: 9214 | CU9: 10026 | CV9: 597746 | CW9: 3272 | CX9: 2945 | CY9: 1996 | CZ9: 4511 | DA9: 2658 | DB9: 15382 | DC9: 613128 | DD9: 0 | DE9: 60 | DF9: 240 | DG9: 78 | DH9: 483 | DI9: 1470 | DJ9: 2331 | DK9: 312 | DL9: 0 | DM9: 0 | DN9: 615771
B10: 115 | C10: Fédération Française de Handball | D10: 4135 | E10: 2454 | F10: 1559 | G10: 2243 | H10: 3025 | I10: 8495 | J10: 3874 | K10: 1657 | L10: 1339 | M10: 4240 | N10: 3789 | O10: 2983 | P10: 20313 | Q10: 13777 | R10: 1418 | S10: 3318 | T10: 4745 | U10: 3106 | V10: 2096 | W10: 6445 | X10: 5267 | Y10: 453 | Z10: 4000 | AA10: 6030 | AB10: 5717 | AC10: 6247 | AD10: 5147 | AE10: 15626 | AF10: 991 | AG10: 470 | AH10: 22702 | AI10: 13033 | AJ10: 2135 | AK10: 17064 | AL10: 12327 | AM10: 10719 | AN10: 1898 | AO10: 5601 | AP10: 8227 | AQ10: 3242 | AR10: 3099 | AS10: 3624 | AT10: 3918 | AU10: 3284 | AV10: 16939 | AW10: 7810 | AX10: 1868 | AY10: 2387 | AZ10: 1265 | BA10: 6479 | BB10: 6317 | BC10: 3605 | BD10: 2057 | BE10: 3485 | BF10: 6730 | BG10: 3329 | BH10: 10645 | BI10: 11518 | BJ10: 1865 | BK10: 12165 | BL10: 5512 | BM10: 1856 | BN10: 5469 | BO10: 3539 | BP10: 8977 | BQ10: 2486 | BR10: 3426 | BS10: 14241 | BT10: 8308 | BU10: 11129 | BV10: 3334 | BW10: 3262 | BX10: 6117 | BY10: 4565 | BZ10: 5532 | CA10: 4821 | CB10: 10301 | CC10: 10412 | CD10: 9706 | CE10: 4089 | CF10: 4179 | CG10: 2630 | CH10: 1840 | CI10: 7801 | CJ10: 11382 | CK10: 5973 | CL10: 4679 | CM10: 4684 | CN10: 2613 | CO10: 2375 | CP10: 1147 | CQ10: 10157 | CR10: 7629 | CS10: 7509 | CT10: 9884 | CU10: 6824 | CV10: 572684 | CW10: 3428 | CX10: 2576 | CY10: 1752 | CZ10: 7128 | DA10: 2993 | DB10: 17877 | DC10: 590561 | DD10: 1 | DE10: 0 | DF10: 1 | DG10: 0 | DH10: 7 | DI10: 581 | DJ10: 590 | DK10: 169 | DL10: 4 | DM10: 0 | DN10: 591324
B11: 117 | C11: Fédération Française de Judo, Jujitsu, Kendo et Disciplines Associées | D11: 5098 | E11: 5389 | F11: 1881 | G11: 1471 | H11: 1425 | I11: 8444 | J11: 1979 | K11: 1223 | L11: 1305 | M11: 1936 | N11: 2335 | O11: 1970 | P11: 13485 | Q11: 6878 | R11: 1046 | S11: 2495 | T11: 5402 | U11: 2248 | V11: 1769 | W11: 5333 | X11: 4319 | Y11: 747 | Z11: 3336 | AA11: 5255 | AB11: 4295 | AC11: 6061 | AD11: 3450 | AE11: 6648 | AF11: 1040 | AG11: 1036 | AH11: 4645 | AI11: 13684 | AJ11: 2261 | AK11: 17009 | AL11: 6822 | AM11: 10151 | AN11: 1771 | AO11: 5804 | AP11: 10941 | AQ11: 2566 | AR11: 3228 | AS11: 1931 | AT11: 5860 | AU11: 1485 | AV11: 11042 | AW11: 6680 | AX11: 1341 | AY11: 2433 | AZ11: 587 | BA11: 6864 | BB11: 3998 | BC11: 4135 | BD11: 1328 | BE11: 2721 | BF11: 5973 | BG11: 1361 | BH11: 6217 | BI11: 9048 | BJ11: 1850 | BK11: 20593 | BL11: 9078 | BM11: 2172 | BN11: 10374 | BO11: 5286 | BP11: 5711 | BQ11: 1569 | BR11: 4506 | BS11: 9634 | BT11: 5608 | BU11: 14644 | BV11: 2066 | BW11: 4504 | BX11: 3666 | BY11: 3330 | BZ11: 6634 | CA11: 10012 | CB11: 11868 | CC11: 16012 | CD11: 15849 | CE11: 2557 | CF11: 5109 | CG11: 2804 | CH11: 2645 | CI11: 6791 | CJ11: 3758 | CK11: 4778 | CL11: 3969 | CM11: 3454 | CN11: 4082 | CO11: 2508 | CP11: 1359 | CQ11: 13162 | CR11: 16059 | CS11: 12588 | CT11: 11178 | CU11: 12517 | CV11: 535469 | CW11: 1990 | CX11: 2393 | CY11: 2016 | CZ11: 3494 | DA11: 526 | DB11: 10419 | DC11: 545888 | DD11: 84 | DE11: 98 | DF11: 0 | DG11: 1 | DH11: 21 | DI11: 1196 | DJ11: 1400 | DK11: 169 | DL11: 214 | DM11: 0 | DN11: 547671
B12: 132 | C12: Fédération Française de Golf | D12: 5587 | E12: 1418 | F12: 1600 | G12: 896 | H12: 610 | I12: 11972 | J12: 1080 | K12: 366 | L12: 643 | M12: 999 | N12: 1535 | O12: 841 | P12: 14488 | Q12: 4714 | R12: 698 | S12: 1923 | T12: 6433 | U12: 1310 | V12: 1114 | W12: 2988 | X12: 3902 | Y12: 316 | Z12: 2405 | AA12: 1885 | AB12: 2549 | AC12: 2975 | AD12: 1975 | AE12: 3655 | AF12: 1239 | AG12: 609 | AH12: 4068 | AI12: 14038 | AJ12: 1413 | AK12: 17714 | AL12: 5984 | AM12: 7545 | AN12: 591 | AO12: 3539 | AP12: 6129 | AQ12: 1299 | AR12: 5853 | AS12: 1499 | AT12: 3721 | AU12: 819 | AV12: 9939 | AW12: 3307 | AX12: 964 | AY12: 2115 | AZ12: 166 | BA12: 4021 | BB12: 3307 | BC12: 3428 | BD12: 301 | BE12: 942 | BF12: 3012 | BG12: 498 | BH12: 4905 | BI12: 4403 | BJ12: 559 | BK12: 14078 | BL12: 4232 | BM12: 1119 | BN12: 5247 | BO12: 4089 | BP12: 10770 | BQ12: 1649 | BR12: 2037 | BS12: 5865 | BT12: 3261 | BU12: 13711 | BV12: 469 | BW12: 1880 | BX12: 2236 | BY12: 2817 | BZ12: 8102 | CA12: 23298 | CB12: 6981 | CC12: 7191 | CD12: 19797 | CE12: 1517 | CF12: 1838 | CG12: 2489 | CH12: 1284 | CI12: 10737 | CJ12: 3532 | CK12: 3575 | CL12: 1895 | CM12: 1970 | CN12: 1123 | CO12: 1105 | CP12: 507 | CQ12: 7682 | CR12: 22300 | CS12: 2583 | CT12: 6928 | CU12: 6858 | CV12: 415556 | CW12: 701 | CX12: 514 | CY12: 217 | CZ12: 3162 | DA12: 68 | DB12: 4662 | DC12: 420218 | DD12: 1 | DE12: 30 | DF12: 72 | DG12: 1 | DH12: 897 | DI12: 1269 | DJ12: 2270 | DK12: 1184 | DL12: 18864 | DM12: 0 | DN12: 442536
B13: 133 | C13: Fédération Française de Rugby | D13: 6496 | E13: 1688 | F13: 2573 | G13: 929 | H13: 817 | I13: 3606 | J13: 4470 | K13: 538 | L13: 3677 | M13: 788 | N13: 6962 | O13: 3985 | P13: 10754 | Q13: 1806 | R13: 3226 | S13: 2975 | T13: 5798 | U13: 2221 | V13: 5569 | W13: 3444 | X13: 1940 | Y13: 515 | Z13: 6070 | AA13: 1775 | AB13: 7182 | AC13: 2401 | AD13: 1977 | AE13: 4920 | AF13: 792 | AG13: 916 | AH13: 5294 | AI13: 21749 | AJ13: 6157 | AK13: 18260 | AL13: 11754 | AM13: 3626 | AN13: 1318 | AO13: 3224 | AP13: 16094 | AQ13: 2315 | AR13: 10733 | AS13: 1870 | AT13: 2619 | AU13: 1715 | AV13: 6173 | AW13: 3217 | AX13: 3829 | AY13: 7553 | AZ13: 683 | BA13: 2770 | BB13: 1637 | BC13: 1443 | BD13: 421 | BE13: 608 | BF13: 1931 | BG13: 555 | BH13: 4194 | BI13: 1686 | BJ13: 1369 | BK13: 6929 | BL13: 2718 | BM13: 721 | BN13: 2383 | BO13: 8202 | BP13: 17462 | BQ13: 6233 | BR13: 7090 | BS13: 2757 | BT13: 1681 | BU13: 9387 | BV13: 479 | BW13: 5166 | BX13: 997 | BY13: 3179 | BZ13: 4345 | CA13: 5142 | CB13: 4336 | CC13: 5110 | CD13: 8030 | CE13: 2250 | CF13: 981 | CG13: 8283 | CH13: 5440 | CI13: 8856 | CJ13: 4467 | CK13: 2589 | CL13: 1888 | CM13: 3152 | CN13: 759 | CO13: 1530 | CP13: 232 | CQ13: 6515 | CR13: 8502 | CS13: 4310 | CT13: 4184 | CU13: 3292 | CV13: 415184 | CW13: 1284 | CX13: 967 | CY13: 1159 | CZ13: 3128 | DA13: 882 | DB13: 7420 | DC13: 422604 | DD13: 48 | DE13: 145 | DF13: 185 | DG13: 365 | DH13: 3 | DI13: 360 | DJ13: 1106 | DK13: 91 | DL13: 492 | DM13: 0 | DN13: 424293
B14: 119 | C14: Fédération Française de Natation | D14: 3258 | E14: 2143 | F14: 2110 | G14: 756 | H14: 1832 | I14: 11680 | J14: 1918 | K14: 2157 | L14: 887 | M14: 806 | N14: 989 | O14: 1506 | P14: 18858 | Q14: 3742 | R14: 399 | S14: 1509 | T14: 2293 | U14: 1858 | V14: 774 | W14: 3672 | X14: 2609 | Y14: 393 | Z14: 1217 | AA14: 2453 | AB14: 2492 | AC14: 3396 | AD14: 1460 | AE14: 3371 | AF14: 529 | AG14: 1800 | AH14: 3156 | AI14: 10218 | AJ14: 802 | AK14: 7720 | AL14: 5848 | AM14: 4272 | AN14: 1038 | AO14: 3134 | AP14: 9940 | AQ14: 1465 | AR14: 1828 | AS14: 2119 | AT14: 3652 | AU14: 1426 | AV14: 8444 | AW14: 3007 | AX14: 1325 | AY14: 1048 | AZ14: 133 | BA14: 4103 | BB14: 2808 | BC14: 2289 | BD14: 580 | BE14: 1279 | BF14: 2859 | BG14: 783 | BH14: 2741 | BI14: 5621 | BJ14: 1243 | BK14: 9825 | BL14: 4302 | BM14: 815 | BN14: 6764 | BO14: 4782 | BP14: 4780 | BQ14: 1227 | BR14: 2696 | BS14: 8990 | BT14: 4761 | BU14: 15786 | BV14: 821 | BW14: 3968 | BX14: 2164 | BY14: 2227 | BZ14: 5292 | CA14: 7691 | CB14: 5664 | CC14: 8758 | CD14: 12499 | CE14: 1515 | CF14: 2130 | CG14: 1945 | CH14: 926 | CI14: 12776 | CJ14: 3405 | CK14: 2290 | CL14: 4185 | CM14: 1618 | CN14: 1309 | CO14: 2911 | CP14: 843 | CQ14: 12070 | CR14: 12265 | CS14: 7725 | CT14: 11626 | CU14: 9974 | CV14: 381073 | CW14: 1668 | CX14: 2132 | CY14: 2708 | CZ14: 6739 | DA14: 14 | DB14: 13261 | DC14: 394334 | DD14: 86 | DE14: 13 | DF14: 202 | DG14: 0 | DH14: 3399 | DI14: 3762 | DJ14: 7462 | DK14: 139 | DL14: 436 | DM14: 0 | DN14: 402371
B15: 113 | C15: Fédération Française de Gymnastique | D15: 6636 | E15: 2903 | F15: 2118 | G15: 738 | H15: 1034 | I15: 6695 | J15: 1639 | K15: 1785 | L15: 754 | M15: 1127 | N15: 1459 | O15: 1230 | P15: 7848 | Q15: 4254 | R15: 119 | S15: 1497 | T15: 2853 | U15: 2676 | V15: 953 | W15: 2712 | X15: 2837 | Y15: 22 | Z15: 1327 | AA15: 2854 | AB15: 2283 | AC15: 4591 | AD15: 1747 | AE15: 3110 | AF15: 900 | AG15: 916 | AH15: 1824 | AI15: 6532 | AJ15: 980 | AK15: 9394 | AL15: 4136 | AM15: 5591 | AN15: 676 | AO15: 2428 | AP15: 3236 | AQ15: 1404 | AR15: 1241 | AS15: 1873 | AT15: 2550 | AU15: 1268 | AV15: 5131 | AW15: 4620 | AX15: 1020 | AY15: 1829 | AZ15: 3 | BA15: 4771 | BB15: 3456 | BC15: 2788 | BD15: 1304 | BE15: 1494 | BF15: 4895 | BG15: 250 | BH15: 2147 | BI15: 7913 | BJ15: 1407 | BK15: 10117 | BL15: 4260 | BM15: 879 | BN15: 4425 | BO15: 2756 | BP15: 2389 | BQ15: 473 | BR15: 1230 | BS15: 9370 | BT15: 6819 | BU15: 11439 | BV15: 1451 | BW15: 3742 | BX15: 3700 | BY15: 1678 | BZ15: 4268 | CA15: 3807 | CB15: 10881 | CC15: 9000 | CD15: 9272 | CE15: 4365 | CF15: 1527 | CG15: 2023 | CH15: 1060 | CI15: 5267 | CJ15: 3531 | CK15: 3921 | CL15: 3846 | CM15: 1211 | CN15: 2364 | CO15: 1675 | CP15: 1143 | CQ15: 6654 | CR15: 11134 | CS15: 7593 | CT15: 9149 | CU15: 6139 | CV15: 332336 | CW15: 1167 | CX15: 1547 | CY15: 907 | CZ15: 4413 | DA15: 110 | DB15: 8144 | DC15: 340480 | DD15: 0 | DE15: 0 | DF15: 64 | DG15: 0 | DH15: 0 | DI15: 965 | DJ15: 1029 | DK15: 465 | DL15: 13 | DM15: 0 | DN15: 341987
B16: 101 | C16: Fédération Française d'Athlétisme | D16: 2575 | E16: 2531 | F16: 1380 | G16: 671 | H16: 842 | I16: 4411 | J16: 1135 | K16: 2490 | L16: 307 | M16: 1460 | N16: 1335 | O16: 1007 | P16: 8166 | Q16: 3565 | R16: 636 | S16: 1766 | T16: 2973 | U16: 1252 | V16: 1381 | W16: 2537 | X16: 3267 | Y16: 602 | Z16: 1436 | AA16: 2145 | AB16: 1865 | AC16: 3077 | AD16: 1908 | AE16: 3978 | AF16: 773 | AG16: 734 | AH16: 3575 | AI16: 6059 | AJ16: 619 | AK16: 8328 | AL16: 4539 | AM16: 7584 | AN16: 809 | AO16: 2911 | AP16: 5556 | AQ16: 1267 | AR16: 1836 | AS16: 2163 | AT16: 3351 | AU16: 1061 | AV16: 9759 | AW16: 3391 | AX16: 769 | AY16: 1315 | AZ16: 512 | BA16: 5913 | BB16: 2841 | BC16: 2503 | BD16: 696 | BE16: 2442 | BF16: 3095 | BG16: 604 | BH16: 4638 | BI16: 3642 | BJ16: 737 | BK16: 9908 | BL16: 4314 | BM16: 822 | BN16: 6494 | BO16: 3422 | BP16: 3600 | BQ16: 1449 | BR16: 1356 | BS16: 4242 | BT16: 3001 | BU16: 6638 | BV16: 594 | BW16: 1928 | BX16: 3598 | BY16: 2164 | BZ16: 3919 | CA16: 4063 | CB16: 5826 | CC16: 7415 | CD16: 8482 | CE16: 1462 | CF16: 3153 | CG16: 2371 | CH16: 840 | CI16: 5422 | CJ16: 2431 | CK16: 4072 | CL16: 1503 | CM16: 2331 | CN16: 2423 | CO16: 1402 | CP16: 573 | CQ16: 7397 | CR16: 8537 | CS16: 3844 | CT16: 6702 | CU16: 6051 | CV16: 298469 | CW16: 2690 | CX16: 2723 | CY16: 684 | CZ16: 5637 | DA16: 277 | DB16: 12011 | DC16: 310480 | DD16: 97 | DE16: 17 | DF16: 212 | DG16: 117 | DH16: 128 | DI16: 883 | DJ16: 1454 | DK16: 89 | DL16: 1934 | DM16: 0 | DN16: 313957
B17: 128 | C17: Fédération Française de Voile | D17: 1370 | E17: 623 | F17: 395 | G17: 704 | H17: 902 | I17: 10966 | J17: 528 | K17: 368 | L17: 261 | M17: 539 | N17: 1760 | O17: 318 | P17: 16544 | Q17: 5703 | R17: 197 | S17: 484 | T17: 10206 | U17: 403 | V17: 185 | W17: 1418 | X17: 11154 | Y17: 126 | Z17: 263 | AA17: 1001 | AB17: 1134 | AC17: 1636 | AD17: 809 | AE17: 11704 | AF17: 1940 | AG17: 927 | AH17: 1290 | AI17: 4339 | AJ17: 248 | AK17: 10031 | AL17: 6909 | AM17: 10870 | AN17: 145 | AO17: 1643 | AP17: 4132 | AQ17: 264 | AR17: 1202 | AS17: 959 | AT17: 872 | AU17: 223 | AV17: 13815 | AW17: 1952 | AX17: 149 | AY17: 229 | AZ17: 127 | BA17: 2275 | BB17: 6053 | BC17: 928 | BD17: 191 | BE17: 494 | BF17: 885 | BG17: 125 | BH17: 12214 | BI17: 1026 | BJ17: 298 | BK17: 6074 | BL17: 1242 | BM17: 321 | BN17: 3182 | BO17: 1117 | BP17: 2380 | BQ17: 230 | BR17: 1391 | BS17: 1795 | BT17: 1233 | BU17: 7528 | BV17: 325 | BW17: 808 | BX17: 1269 | BY17: 2750 | BZ17: 7115 | CA17: 17681 | CB17: 5398 | CC17: 1981 | CD17: 8292 | CE17: 586 | CF17: 1215 | CG17: 555 | CH17: 300 | CI17: 13708 | CJ17: 870 | CK17: 5132 | CL17: 667 | CM17: 463 | CN17: 429 | CO17: 469 | CP17: 151 | CQ17: 3144 | CR17: 11892 | CS17: 2062 | CT17: 4048 | CU17: 1927 | CV17: 288186 | CW17: 2039 | CX17: 1692 | CY17: 676 | CZ17: 1225 | DA17: 215 | DB17: 5847 | DC17: 294033 | DD17: 347 | DE17: 262 | DF17: 99 | DG17: 30 | DH17: 85 | DI17: 1613 | DJ17: 2436 | DK17: 278 | DL17: 5295 | DM17: 0 | DN17: 302042
... B43: 120 | C43: Fédération Française de Pentathlon Moderne | D43: 1 | E43: 121 | F43: 0 | G43: 28 | H43: 2 | I43: 13 | J43: 2 | K43: 0 | L43: 22 | M43: 1 | N43: 5 | O43: 35 | P43: 221 | Q43: 0 | R43: 1 | S43: 1 | T43: 16 | U43: 0 | V43: 2 | W43: 2 | X43: 13 | Y43: 0 | Z43: 9 | AA43: 2 | AB43: 21 | AC43: 0 | AD43: 3 | AE43: 2 | AF43: 0 | AG43: 0 | AH43: 9 | AI43: 13 | AJ43: 22 | AK43: 71 | AL43: 2 | AM43: 84 | AN43: 0 | AO43: 0 | AP43: 40 | AQ43: 0 | AR43: 4 | AS43: 0 | AT43: 3 | AU43: 0 | AV43: 4 | AW43: 0 | AX43: 0 | AY43: 0 | AZ43: 0 | BA43: 0 | BB43: 19 | BC43: 1 | BD43: 0 | BE43: 1 | BF43: 0 | BG43: 0 | BH43: 3 | BI43: 0 | BJ43: 2 | BK43: 4 | BL43: 127 | BM43: 1 | BN43: 0 | BO43: 0 | BP43: 38 | BQ43: 0 | BR43: 807 | BS43: 31 | BT43: 0 | BU43: 23 | BV43: 0 | BW43: 0 | BX43: 0 | BY43: 52 | BZ43: 6 | CA43: 255 | CB43: 0 | CC43: 136 | CD43: 89 | CE43: 0 | CF43: 1 | CG43: 1 | CH43: 0 | CI43: 12 | CJ43: 10 | CK43: 0 | CL43: 0 | CM43: 8 | CN43: 0 | CO43: 0 | CP43: 0 | CQ43: 44 | CR43: 71 | CS43: 35 | CT43: 161 | CU43: 10 | CV43: 2723 | CW43: 0 | CX43: 0 | CY43: 0 | CZ43: 6 | DA43: 0 | DB43: 6 | DC43: 2729 | DD43: 0 | DE43: 0 | DF43: 0 | DG43: 0 | DH43: 0 | DI43: 0 | DJ43: 0 | DK43: 0 | DL43: 0 | DM43: 0 | DN43: 2729
A44: 2. Délégataire non-olympique(54) | D44: 25734 | E44: 10741 | F44: 11880 | G44: 7988 | H44: 10146 | I44: 40051 | J44: 17092 | K44: 5971 | L44: 7834 | M44: 7299 | N44: 16701 | O44: 18937 | P44: 67588 | Q44: 16196 | R44: 5294 | S44: 10660 | T44: 21166 | U44: 7855 | V44: 7665 | W44: 17511 | X44: 19338 | Y44: 3411 | Z44: 11183 | AA44: 16033 | AB44: 24415 | AC44: 16660 | AD44: 10702 | AE44: 25268 | AF44: 4774 | AG44: 6204 | AH44: 28272 | AI44: 51682 | AJ44: 9589 | AK44: 48736 | AL44: 43961 | AM44: 31975 | AN44: 5903 | AO44: 18977 | AP44: 53990 | AQ44: 7911 | AR44: 21100 | AS44: 9831 | AT44: 24957 | AU44: 9458 | AV44: 35314 | AW44: 22962 | AX44: 9039 | AY44: 14184 | AZ44: 3553 | BA44: 18190 | BB44: 12517 | BC44: 11596 | BD44: 3455 | BE44: 8340 | BF44: 19135 | BG44: 4201 | BH44: 21645 | BI44: 24943 | BJ44: 6765 | BK44: 45294 | BL44: 20846 | BM44: 6888 | BN44: 25865 | BO44: 20475 | BP44: 30611 | BQ44: 10041 | BR44: 21922 | BS44: 24931 | BT44: 19048 | BU44: 51983 | BV44: 6607 | BW44: 15896 | BX44: 16044 | BY44: 22368 | BZ44: 40398 | CA44: 34247 | CB44: 26102 | CC44: 39159 | CD44: 40114 | CE44: 10799 | CF44: 12839 | CG44: 17370 | CH44: 10698 | CI44: nd | CJ44: 23719 | CK44: 19879 | CL44: 13515 | CM44: 9674 | CN44: 8643 | CO44: 8797 | CP44: 3491 | CQ44: 35847 | CR44: 33784 | CS44: 22375 | CT44: 27206 | CU44: 29840 | CV44: 1906871 | CW44: 8825 | CX44: 7793 | CY44: 2329 | CZ44: 19419 | DA44: 2309 | DB44: 40675 | DC44: 1947546 | DD44: 237 | DE44: 307 | DF44: 488 | DG44: 189 | DH44: 3577 | DI44: 4272 | DJ44: 9070 | DK44: 682 | DL44: 12578 | DM44: 542 | DN44: 1970418
B45: 242 | C45: Fédération Française de Pétanque et Jeu Provençal | D45: 3432 | E45: 2821 | F45: 4561 | G45: 2061 | H45: 1524 | I45: 7452 | J45: 4756 | K45: 1907 | L45: 2356 | M45: 710 | N45: 4287 | O45: 4016 | P45: 11533 | Q45: 1864 | R45: 2066 | S45: 2446 | T45: 3593 | U45: 2125 | V45: 1731 | W45: 2331 | X45: 1918 | Y45: 1144 | Z45: 2246 | AA45: 1997 | AB45: 4968 | AC45: 1650 | AD45: 1031 | AE45: 4543 | AF45: 1058 | AG45: 1462 | AH45: 7085 | AI45: 10946 | AJ45: 2785 | AK45: 6793 | AL45: 9650 | AM45: 3295 | AN45: 1240 | AO45: 2175 | AP45: 5225 | AQ45: 1655 | AR45: 3951 | AS45: 1676 | AT45: 3494 | AU45: 3072 | AV45: 3029 | AW45: 2747 | AX45: 2614 | AY45: 3216 | AZ45: 1018 | BA45: 3478 | BB45: 2378 | BC45: 1302 | BD45: 540 | BE45: 2254 | BF45: 2670 | BG45: 580 | BH45: 2118 | BI45: 5230 | BJ45: 1814 | BK45: 5619 | BL45: 3082 | BM45: 1075 | BN45: 2344 | BO45: 6093 | BP45: 2140 | BQ45: 1856 | BR45: 4501 | BS45: 2378 | BT45: 1367 | BU45: 4883 | BV45: 1421 | BW45: 4194 | BX45: 2233 | BY45: 1379 | BZ45: 2010 | CA45: 1737 | CB45: 2980 | CC45: 4887 | CD45: 2545 | CE45: 2314 | CF45: 1582 | CG45: 4447 | CH45: 3625 | CI45: 6164 | CJ45: 5636 | CK45: 3790 | CL45: 1967 | CM45: 2757 | CN45: 1622 | CO45: 1963 | CP45: 392 | CQ45: 3173 | CR45: 2013 | CS45: 1995 | CT45: 2365 | CU45: 2719 | CV45: 294867 | CW45: 785 | CX45: 1404 | CY45: 260 | CZ45: 2493 | DA45: 327 | DB45: 5269 | DC45: 300136 | DD45: 0 | DE45: 104 | DF45: 88 | DG45: 132 | DH45: 1892 | DI45: 489 | DJ45: 2705 | DK45: 79 | DL45: 0 | DM45: 0 | DN45: 302920
B46: 229 | C46: Fédération Française de Karaté et Disciplines Associées | D46: 1835 | E46: 1595 | F46: 818 | G46: 656 | H46: 443 | I46: 7122 | J46: 1040 | K46: 1144 | L46: 471 | M46: 1027 | N46: 1064 | O46: 777 | P46: 8713 | Q46: 2498 | R46: 114 | S46: 691 | T46: 1854 | U46: 855 | V46: 1120 | W46: 2061 | X46: 1256 | Y46: 207 | Z46: 1186 | AA46: 2523 | AB46: 1094 | AC46: 3587 | AD46: 1556 | AE46: 2304 | AF46: 519 | AG46: 743 | AH46: 2991 | AI46: 5587 | AJ46: 476 | AK46: 5554 | AL46: 3834 | AM46: 2856 | AN46: 746 | AO46: 2645 | AP46: 5038 | AQ46: 511 | AR46: 1225 | AS46: 657 | AT46: 3251 | AU46: 674 | AV46: 4807 | AW46: 3047 | AX46: 866 | AY46: 1014 | AZ46: 202 | BA46: 2215 | BB46: 1459 | BC46: 1534 | BD46: 278 | BE46: 659 | BF46: 2575 | BG46: 742 | BH46: 2639 | BI46: 3838 | BJ46: 566 | BK46: 9078 | BL46: 4316 | BM46: 871 | BN46: 3645 | BO46: 2155 | BP46: 1942 | BQ46: 992 | BR46: 1833 | BS46: 4138 | BT46: 3578 | BU46: 6323 | BV46: 597 | BW46: 1274 | BX46: 1524 | BY46: 2221 | BZ46: 2570 | CA46: 6084 | CB46: 4361 | CC46: 8315 | CD46: 9597 | CE46: 861 | CF46: 1066 | CG46: 1197 | CH46: 869 | CI46: 6430 | CJ46: 1887 | CK46: 1954 | CL46: 1336 | CM46: 713 | CN46: 717 | CO46: 1099 | CP46: 271 | CQ46: 7803 | CR46: 6769 | CS46: 5878 | CT46: 5946 | CU46: 7896 | CV46: 241465 | CW46: 1229 | CX46: 1301 | CY46: 401 | CZ46: 3473 | DA46: 206 | DB46: 6610 | DC46: 248075 | DD46: 65 | DE46: 13 | DF46: 215 | DG46: 0 | DH46: 230 | DI46: 916 | DJ46: 1439 | DK46: 138 | DL46: 67 | DM46: 0 | DN46: 249719
B47: 245 | C47: Fédération Française de la Randonnée Pédestre | D47: 2207 | E47: 782 | F47: 968 | G47: 1023 | H47: 594 | I47: 5328 | J47: 1987 | K47: 222 | L47: 877 | M47: 792 | N47: 1634 | O47: 3359 | P47: 8529 | Q47: 1397 | R47: 384 | S47: 1384 | T47: 3689 | U47: 791 | V47: 790 | W47: 3824 | X47: 4986 | Y47: 564 | Z47: 1812 | AA47: 2021 | AB47: 3863 | AC47: 2099 | AD47: 2118 | AE47: 2438 | AF47: 221 | AG47: 194 | AH47: 3023 | AI47: 3259 | AJ47: 1396 | AK47: 5750 | AL47: 4522 | AM47: 5401 | AN47: 893 | AO47: 4155 | AP47: 3560 | AQ47: 970 | AR47: 1884 | AS47: 2129 | AT47: 4393 | AU47: 954 | AV47: 5755 | AW47: 4459 | AX47: 1179 | AY47: 2536 | AZ47: 616 | BA47: 3143 | BB47: 1198 | BC47: 1477 | BD47: 455 | BE47: 1341 | BF47: 2828 | BG47: 632 | BH47: 3924 | BI47: 2023 | BJ47: 1499 | BK47: 4554 | BL47: 1970 | BM47: 697 | BN47: 3523 | BO47: 1220 | BP47: 2886 | BQ47: 540 | BR47: 4272 | BS47: 672 | BT47: 125 | BU47: 3717 | BV47: 785 | BW47: 1221 | BX47: 2141 | BY47: 1287 | BZ47: 3917 | CA47: 1718 | CB47: 3983 | CC47: 5939 | CD47: 4509 | CE47: 2652 | CF47: 2028 | CG47: 2580 | CH47: 863 | CI47: 8147 | CJ47: 3142 | CK47: 3118 | CL47: 2880 | CM47: 837 | CN47: 541 | CO47: 1124 | CP47: 186 | CQ47: 5960 | CR47: 2721 | CS47: 2414 | CT47: 2324 | CU47: 3382 | CV47: 230806 | CW47: 584 | CX47: 1073 | CY47: 26 | CZ47: 1527 | DA47: 47 | DB47: 3257 | DC47: 234063 | DD47: 0 | DE47: 0 | DF47: 98 | DG47: 0 | DH47: 308 | DI47: 0 | DJ47: 406 | DK47: 20 | DL47: 266 | DM47: 0 | DN47: 234755
B48: 221 | C48: Fédération Française d'Études et Sports Sous-Marins | D48: 1351 | E48: 679 | F48: 514 | G48: 286 | H48: 347 | I48: 2614 | J48: 578 | K48: 233 | L48: 283 | M48: 492 | N48: 659 | O48: 363 | P48: 5324 | Q48: 1325 | R48: 134 | S48: 482 | T48: 1680 | U48: 400 | V48: 353 | W48: 848 | X48: 1377 | Y48: 87 | Z48: 472 | AA48: 789 | AB48: 1224 | AC48: 951 | AD48: 724 | AE48: 2560 | AF48: 590 | AG48: 471 | AH48: 1379 | AI48: 3817 | AJ48: 256 | AK48: 3995 | AL48: 2498 | AM48: 2698 | AN48: 310 | AO48: 1401 | AP48: 3300 | AQ48: 333 | AR48: 847 | AS48: 468 | AT48: 1120 | AU48: 278 | AV48: 2928 | AW48: 1394 | AX48: 317 | AY48: 580 | AZ48: 27 | BA48: 1089 | BB48: 991 | BC48: 893 | BD48: 263 | BE48: 450 | BF48: 1322 | BG48: 319 | BH48: 2114 | BI48: 1828 | BJ48: 169 | BK48: 3315 | BL48: 1266 | BM48: 350 | BN48: 1411 | BO48: 1312 | BP48: 961 | BQ48: 258 | BR48: 1177 | BS48: 2103 | BT48: 1433 | BU48: 4391 | BV48: 297 | BW48: 874 | BX48: 813 | BY48: 786 | BZ48: 1786 | CA48: 4286 | CB48: 2097 | CC48: 2969 | CD48: 4054 | CE48: 578 | CF48: 867 | CG48: 868 | CH48: 312 | CI48: 3352 | CJ48: 1096 | CK48: 1083 | CL48: 805 | CM48: 602 | CN48: 575 | CO48: 527 | CP48: 333 | CQ48: 3277 | CR48: 4639 | CS48: 1759 | CT48: 2791 | CU48: 2879 | CV48: 127856 | CW48: 891 | CX48: 911 | CY48: 203 | CZ48: 1719 | DA48: 133 | DB48: 3857 | DC48: 131713 | DD48: 65 | DE48: 158 | DF48: 28 | DG48: 14 | DH48: 716 | DI48: 664 | DJ48: 1645 | DK48: 19 | DL48: 1368 | DM48: 0 | DN48: 134745
B49: 271 | C49: Fédération Française des Clubs Alpins et de Montagne | D49: 2280 | E49: 128 | F49: 207 | G49: 720 | H49: 3547 | I49: 2817 | J49: 918 | K49: 149 | L49: 805 | M49: 391 | N49: 574 | O49: 554 | P49: 3128 | Q49: 309 | R49: 447 | S49: 282 | T49: 358 | U49: 209 | V49: 391 | W49: 695 | X49: 30 | Y49: 231 | Z49: 308 | AA49: 1672 | AB49: 2211 | AC49: 190 | AD49: 29 | AE49: 314 | AF49: 83 | AG49: 219 | AH49: 1229 | AI49: 3821 | AJ49: 523 | AK49: 1566 | AL49: 1522 | AM49: 588 | AN49: 63 | AO49: 415 | AP49: 10455 | AQ49: 715 | AR49: 248 | AS49: 237 | AT49: 1251 | AU49: 776 | AV49: 1533 | AW49: 796 | AX49: 308 | AY49: 322 | AZ49: 403 | BA49: 1004 | BB49: 217 | BC49: 557 | BD49: 57 | BE49: 36 | BF49: 599 | BG49: 65 | BH49: 356 | BI49: 417 | BJ49: 29 | BK49: 661 | BL49: 483 | BM49: 280 | BN49: 574 | BO49: 1126 | BP49: 2691 | BQ49: 1515 | BR49: 917 | BS49: 1541 | BT49: 1434 | BU49: 4101 | BV49: 446 | BW49: 1158 | BX49: 1211 | BY49: 6533 | BZ49: 14266 | CA49: 2033 | CB49: 959 | CC49: 478 | CD49: 621 | CE49: 248 | CF49: 26 | CG49: 480 | CH49: 107 | CI49: 1635 | CJ49: 815 | CK49: 322 | CL49: 119 | CM49: 267 | CN49: 658 | CO49: 390 | CP49: 420 | CQ49: 294 | CR49: 779 | CS49: 474 | CT49: 360 | CU49: 104 | CV49: 104830 | CW49: 0 | CX49: 0 | CY49: 2 | CZ49: 92 | DA49: 1 | DB49: 95 | DC49: 104925 | DD49: 0 | DE49: 0 | DF49: 0 | DG49: 0 | DH49: 3 | DI49: 5 | DJ49: 8 | DK49: 29 | DL49: 3304 | DM49: 0 | DN49: 108266
B50: 218 | C50: Fédération Française de Cyclotourisme | D50: 1231 | E50: 377 | F50: 900 | G50: 296 | H50: 202 | I50: 329 | J50: 1091 | K50: 112 | L50: 423 | M50: 659 | N50: 1111 | O50: 607 | P50: 2281 | Q50: 918 | R50: 372 | S50: 755 | T50: 1239 | U50: 573 | V50: 900 | W50: 1380 | X50: 2393 | Y50: 136 | Z50: 477 | AA50: 304 | AB50: 1602 | AC50: 1293 | AD50: 634 | AE50: 2399 | AF50: 25 | AG50: 3 | AH50: 961 | AI50: 1823 | AJ50: 722 | AK50: 1747 | AL50: 1442 | AM50: 3274 | AN50: 344 | AO50: 1234 | AP50: 3268 | AQ50: 453 | AR50: 1096 | AS50: 1259 | AT50: 1639 | AU50: 513 | AV50: 3469 | AW50: 984 | AX50: 650 | AY50: 298 | AZ50: 220 | BA50: 2047 | BB50: 836 | BC50: 571 | BD50: 245 | BE50: 1073 | BF50: 1095 | BG50: 159 | BH50: 1861 | BI50: 1664 | BJ50: 610 | BK50: 2471 | BL50: 790 | BM50: 1040 | BN50: 1935 | BO50: 982 | BP50: 1666 | BQ50: 602 | BR50: 1017 | BS50: 1455 | BT50: 853 | BU50: 2675 | BV50: 399 | BW50: 566 | BX50: 1616 | BY50: 1520 | BZ50: 1720 | CA50: 547 | CB50: 1329 | CC50: 1549 | CD50: 3247 | CE50: 876 | CF50: 403 | CG50: 932 | CH50: 765 | CI50: 2543 | CJ50: 1728 | CK50: 1722 | CL50: 1437 | CM50: 212 | CN50: 558 | CO50: 328 | CP50: 160 | CQ50: 1785 | CR50: 1318 | CS50: 418 | CT50: 1118 | CU50: 1300 | CV50: 106161 | CW50: 91 | CX50: 0 | CY50: 1 | CZ50: 133 | DA50: 0 | DB50: 225 | DC50: 106386 | DD50: 0 | DE50: 0 | DF50: 0 | DG50: 0 | DH50: 1 | DI50: 49 | DJ50: 50 | DK50: 3 | DL50: 294 | DM50: 0 | DN50: 106733
B51: 220 | C51: Fédération Française des Échecs | D51: 634 | E51: 283 | F51: 240 | G51: 187 | H51: 190 | I51: 1724 | J51: 123 | K51: 293 | L51: 162 | M51: 153 | N51: 457 | O51: 88 | P51: 3301 | Q51: 732 | R51: 60 | S51: 367 | T51: 658 | U51: 88 | V51: 156 | W51: 461 | X51: 979 | Y51: 5 | Z51: 85 | AA51: 535 | AB51: 322 | AC51: 280 | AD51: 544 | AE51: 1025 | AF51: 172 | AG51: 511 | AH51: 600 | AI51: 1261 | AJ51: 344 | AK51: 2138 | AL51: 1279 | AM51: 1238 | AN51: 62 | AO51: 846 | AP51: 1073 | AQ51: 318 | AR51: 342 | AS51: 139 | AT51: 522 | AU51: 47 | AV51: 1865 | AW51: 1666 | AX51: 348 | AY51: 1212 | AZ51: 89 | BA51: 564 | BB51: 695 | BC51: 975 | BD51: 79 | BE51: 442 | BF51: 1353 | BG51: 84 | BH51: 1036 | BI51: 1116 | BJ51: 71 | BK51: 2273 | BL51: 422 | BM51: 230 | BN51: 634 | BO51: 476 | BP51: 587 | BQ51: 771 | BR51: 561 | BS51: 2097 | BT51: 1136 | BU51: 2590 | BV51: 37 | BW51: 317 | BX51: 716 | BY51: 538 | BZ51: 1280 | CA51: 3275 | CB51: 947 | CC51: 1098 | CD51: 1841 | CE51: 235 | CF51: 235 | CG51: 333 | CH51: 245 | CI51: 1850 | CJ51: 752 | CK51: 581 | CL51: 209 | CM51: 244 | CN51: 231 | CO51: 232 | CP51: 275 | CQ51: 1075 | CR51: 3342 | CS51: 1367 | CT51: 1971 | CU51: 1555 | CV51: 73177 | CW51: 435 | CX51: 567 | CY51: 192 | CZ51: 1507 | DA51: 0 | DB51: 2701 | DC51: 75878 | DD51: 29 | DE51: 6 | DF51: 1 | DG51: 0 | DH51: 3 | DI51: 164 | DJ51: 203 | DK51: 65 | DL51: 0 | DM51: 0 | DN51: 76146
B52: 249 | C52: Fédération Française de Sauvetage et de Secourisme | D52: 390 | E52: 204 | F52: 176 | G52: 63 | H52: 78 | I52: 1383 | J52: 123 | K52: 54 | L52: 115 | M52: 112 | N52: 744 | O52: 477 | P52: 1590 | Q52: 413 | R52: 13 | S52: 694 | T52: 762 | U52: 61 | V52: 15 | W52: 185 | X52: 1144 | Y52: 20 | Z52: 480 | AA52: 305 | AB52: 453 | AC52: 781 | AD52: 215 | AE52: 1852 | AF52: 7 | AG52: 36 | AH52: 662 | AI52: 2700 | AJ52: 143 | AK52: 2378 | AL52: 3817 | AM52: 4465 | AN52: 298 | AO52: 759 | AP52: 1988 | AQ52: 46 | AR52: 2114 | AS52: 324 | AT52: 250 | AU52: 22 | AV52: 727 | AW52: 1132 | AX52: 56 | AY52: 146 | AZ52: 17 | BA52: 404 | BB52: 589 | BC52: 74 | BD52: 43 | BE52: 318 | BF52: 278 | BG52: 29 | BH52: 1262 | BI52: 252 | BJ52: 73 | BK52: 1242 | BL52: 790 | BM52: 58 | BN52: 1205 | BO52: 39 | BP52: 2943 | BQ52: 694 | BR52: 1210 | BS52: 1062 | BT52: 734 | BU52: 1138 | BV52: 47 | BW52: 57 | BX52: 647 | BY52: 784 | BZ52: 652 | CA52: 1865 | CB52: 543 | CC52: 958 | CD52: 1266 | CE52: 283 | CF52: 542 | CG52: 913 | CH52: 640 | CI52: 2310 | CJ52: 1377 | CK52: 895 | CL52: 1391 | CM52: 45 | CN52: 128 | CO52: 312 | CP52: 66 | CQ52: 508 | CR52: 1406 | CS52: 1364 | CT52: 1275 | CU52: 922 | CV52: 70622 | CW52: 1867 | CX52: 211 | CY52: 276 | CZ52: 345 | DA52: 1057 | DB52: 3756 | DC52: 74378 | DD52: 8 | DE52: 3 | DF52: 0 | DG52: 0 | DH52: 1 | DI52: 231 | DJ52: 243 | DK52: 0 | DL52: 3 | DM52: 0 | DN52: 74624
B53: 261 | C53: Fédération Française de Kick Boxing, Muay Thaï et Disciplines Associées | D53: 957 | E53: 212 | F53: 252 | G53: 278 | H53: 11 | I53: 1190 | J53: 323 | K53: 56 | L53: 123 | M53: 475 | N53: 445 | O53: 173 | P53: 4637 | Q53: 666 | R53: 260 | S53: 241 | T53: 523 | U53: 93 | V53: 298 | W53: 353 | X53: 246 | Y53: 121 | Z53: 261 | AA53: 889 | AB53: 580 | AC53: 620 | AD53: 233 | AE53: 1522 | AF53: 308 | AG53: 884 | AH53: 1258 | AI53: 1786 | AJ53: 177 | AK53: 2146 | AL53: 1028 | AM53: 660 | AN53: 102 | AO53: 673 | AP53: 2206 | AQ53: 111 | AR53: 304 | AS53: 34 | AT53: 883 | AU53: 300 | AV53: 731 | AW53: 727 | AX53: 212 | AY53: 300 | AZ53: 6 | BA53: 91 | BB53: 322 | BC53: 441 | BD53: 120 | BE53: 117 | BF53: 852 | BG53: 18 | BH53: 552 | BI53: 1543 | BJ53: 68 | BK53: 1778 | BL53: 569 | BM53: 196 | BN53: 1019 | BO53: 548 | BP53: 572 | BQ53: 315 | BR53: 323 | BS53: 1101 | BT53: 319 | BU53: 1941 | BV53: 227 | BW53: 359 | BX53: 383 | BY53: 239 | BZ53: 754 | CA53: 917 | CB53: 1846 | CC53: 1069 | CD53: 1368 | CE53: 56 | CF53: 213 | CG53: 323 | CH53: 634 | CI53: 1779 | CJ53: 985 | CK53: 437 | CL53: 11 | CM53: 317 | CN53: 181 | CO53: 317 | CP53: 157 | CQ53: 1158 | CR53: 1342 | CS53: 1597 | CT53: 681 | CU53: 1564 | CV53: 62593 | CW53: 64 | CX53: 368 | CY53: 267 | CZ53: 2412 | DA53: 451 | DB53: 3562 | DC53: 66155 | DD53: 0 | DE53: 0 | DF53: 0 | DG53: 0 | DH53: 0 | DI53: 15 | DJ53: 15 | DK53: 112 | DL53: 0 | DM53: 0 | DN53: 66282
B54: 233 | C54: Fédération Française de Motocyclisme | D54: 1236 | E54: 973 | F54: 586 | G54: 419 | H54: 278 | I54: 1116 | J54: 773 | K54: 561 | L54: 206 | M54: 626 | N54: 398 | O54: 531 | P54: 1821 | Q54: 847 | R54: 356 | S54: 455 | T54: 802 | U54: 425 | V54: 352 | W54: 638 | X54: 756 | Y54: 263 | Z54: 608 | AA54: 1021 | AB54: 644 | AC54: 1050 | AD54: 656 | AE54: 757 | AF54: 372 | AG54: 227 | AH54: 1078 | AI54: 1207 | AJ54: 350 | AK54: 1423 | AL54: 1035 | AM54: 983 | AN54: 140 | AO54: 470 | AP54: 972 | AQ54: 536 | AR54: 553 | AS54: 366 | AT54: 706 | AU54: 637 | AV54: 864 | AW54: 749 | AX54: 319 | AY54: 650 | AZ54: 223 | BA54: 584 | BB54: 841 | BC54: 736 | BD54: 308 | BE54: 282 | BF54: 699 | BG54: 339 | BH54: 649 | BI54: 922 | BJ54: 392 | BK54: 1637 | BL54: 1261 | BM54: 536 | BN54: 1550 | BO54: 887 | BP54: 696 | BQ54: 167 | BR54: 344 | BS54: 885 | BT54: 832 | BU54: 896 | BV54: 604 | BW54: 676 | BX54: 892 | BY54: 392 | BZ54: 795 | CA54: 144 | CB54: 1030 | CC54: 996 | CD54: 632 | CE54: 322 | CF54: 940 | CG54: 595 | CH54: 399 | CI54: 1370 | CJ54: 1138 | CK54: 1219 | CL54: 417 | CM54: 376 | CN54: 550 | CO54: 440 | CP54: 200 | CQ54: 696 | CR54: 192 | CS54: 154 | CT54: 182 | CU54: 398 | CV54: 64206 | CW54: 850 | CX54: 218 | CY54: 25 | CZ54: 521 | DA54: 0 | DB54: 1614 | DC54: 65820 | DD54: 0 | DE54: 0 | DF54: 18 | DG54: 0 | DH54: 1 | DI54: 166 | DJ54: 185 | DK54: 27 | DL54: 147 | DM54: 0 | DN54: 66179
B55: 212 | C55: Fédération Française de Savate, Boxe Française et Disciplines Associées | D55: 692 | E55: 207 | F55: 142 | G55: 135 | H55: 29 | I55: 672 | J55: 366 | K55: 124 | L55: 289 | M55: 41 | N55: 521 | O55: 168 | P55: 2054 | Q55: 328 | R55: 254 | S55: 535 | T55: 132 | U55: 175 | V55: 65 | W55: 703 | X55: 365 | Y55: 101 | Z55: 427 | AA55: 190 | AB55: 1332 | AC55: 243 | AD55: 87 | AE55: 597 | AF55: 1 | AG55: 1 | AH55: 1178 | AI55: 1620 | AJ55: 108 | AK55: 1870 | AL55: 1250 | AM55: 797 | AN55: 132 | AO55: 363 | AP55: 1533 | AQ55: 91 | AR55: 443 | AS55: 9 | AT55: 141 | AU55: 177 | AV55: 539 | AW55: 237 | AX55: 89 | AY55: 605 | AZ55: 61 | BA55: 356 | BB55: 77 | BC55: 131 | BD55: 2 | BE55: 8 | BF55: 923 | BG55: 180 | BH55: 1156 | BI55: 486 | BJ55: 27 | BK55: 1945 | BL55: 627 | BM55: 13 | BN55: 654 | BO55: 971 | BP55: 299 | BQ55: 175 | BR55: 754 | BS55: 1019 | BT55: 594 | BU55: 1887 | BV55: 208 | BW55: 293 | BX55: 246 | BY55: 692 | BZ55: 875 | CA55: 2676 | CB55: 451 | CC55: 2232 | CD55: 1556 | CE55: 294 | CF55: 742 | CG55: 323 | CH55: 253 | CI55: 933 | CJ55: 303 | CK55: 398 | CL55: 63 | CM55: 110 | CN55: 52 | CO55: 135 | CP55: 109 | CQ55: 2175 | CR55: 1812 | CS55: 771 | CT55: 1823 | CU55: 2138 | CV55: 56166 | CW55: 196 | CX55: 137 | CY55: 63 | CZ55: 832 | DA55: 10 | DB55: 1238 | DC55: 57404 | DD55: 0 | DE55: 0 | DF55: 0 | DG55: 0 | DH55: 0 | DI55: 132 | DJ55: 132 | DK55: 1 | DL55: 16 | DM55: 0 | DN55: 57553
B56: 206 | C56: Fédération Française du Sport Automobile | D56: 793 | E56: 283 | F56: 300 | G56: 319 | H56: 324 | I56: 1534 | J56: 635 | K56: 132 | L56: 84 | M56: 104 | N56: 221 | O56: 816 | P56: 1242 | Q56: 956 | R56: 168 | S56: 243 | T56: 741 | U56: 222 | V56: 105 | W56: 515 | X56: 277 | Y56: 59 | Z56: 299 | AA56: 777 | AB56: 623 | AC56: 732 | AD56: 277 | AE56: 268 | AF56: 551 | AG56: 501 | AH56: 1077 | AI56: 786 | AJ56: 274 | AK56: 727 | AL56: 979 | AM56: 582 | AN56: 203 | AO56: 490 | AP56: 1028 | AQ56: 285 | AR56: 201 | AS56: 359 | AT56: 1205 | AU56: 420 | AV56: 855 | AW56: 385 | AX56: 232 | AY56: 210 | AZ56: 183 | BA56: 423 | BB56: 602 | BC56: 216 | BD56: 119 | BE56: 400 | BF56: 433 | BG56: 84 | BH56: 384 | BI56: 329 | BJ56: 314 | BK56: 942 | BL56: 282 | BM56: 255 | BN56: 1102 | BO56: 689 | BP56: 843 | BQ56: 128 | BR56: 312 | BS56: 394 | BT56: 570 | BU56: 999 | BV56: 506 | BW56: 762 | BX56: 1061 | BY56: 486 | BZ56: 1132 | CA56: 588 | CB56: 946 | CC56: 486 | CD56: 584 | CE56: 237 | CF56: 296 | CG56: 648 | CH56: 188 | CI56: 1426 | CJ56: 667 | CK56: 516 | CL56: 248 | CM56: 372 | CN56: 588 | CO56: 367 | CP56: 125 | CQ56: 592 | CR56: 426 | CS56: 99 | CT56: 193 | CU56: 194 | CV56: 48135 | CW56: 414 | CX56: 179 | CY56: 89 | CZ56: 1059 | DA56: 0 | DB56: 1741 | DC56: 49876 | DD56: 0 | DE56: 2 | DF56: 1 | DG56: 0 | DH56: 58 | DI56: 304 | DJ56: 365 | DK56: 51 | DL56: 22 | DM56: 0 | DN56: 50314
... B94: 227 | C94: Fédération Française de Jeu de Paume | D94: 0 | E94: 0 | F94: 0 | G94: 0 | H94: 0 | I94: 0 | J94: 0 | K94: 0 | L94: 0 | M94: 0 | N94: 0 | O94: 0 | P94: 0 | Q94: 0 | R94: 0 | S94: 0 | T94: 0 | U94: 0 | V94: 0 | W94: 0 | X94: 0 | Y94: 0 | Z94: 0 | AA94: 0 | AB94: 0 | AC94: 0 | AD94: 0 | AE94: 0 | AF94: 0 | AG94: 0 | AH94: 0 | AI94: 0 | AJ94: 0 | AK94: 0 | AL94: 0 | AM94: 0 | AN94: 0 | AO94: 0 | AP94: 0 | AQ94: 0 | AR94: 0 | AS94: 0 | AT94: 0 | AU94: 0 | AV94: 0 | AW94: 0 | AX94: 0 | AY94: 0 | AZ94: 0 | BA94: 0 | BB94: 0 | BC94: 0 | BD94: 0 | BE94: 0 | BF94: 0 | BG94: 0 | BH94: 0 | BI94: 0 | BJ94: 0 | BK94: 285 | BL94: 45 | BM94: 0 | BN94: 0 | BO94: 0 | BP94: 0 | BQ94: 0 | BR94: 0 | BS94: 0 | BT94: 0 | BU94: 0 | BV94: 0 | BW94: 0 | BX94: 0 | BY94: 0 | BZ94: 0 | CA94: 0 | CB94: 0 | CC94: 0 | CD94: 0 | CE94: 0 | CF94: 271 | CG94: 0 | CH94: 0 | CI94: 0 | CJ94: 0 | CK94: 0 | CL94: 0 | CM94: 0 | CN94: 0 | CO94: 0 | CP94: 0 | CQ94: 0 | CR94: 0 | CS94: 0 | CT94: 0 | CU94: 0 | CV94: 601 | CW94: 0 | CX94: 0 | CY94: 0 | CZ94: 0 | DA94: 0 | DB94: 0 | DC94: 601 | DD94: 0 | DE94: 0 | DF94: 0 | DG94: 0 | DH94: 0 | DI94: 0 | DJ94: 0 | DK94: 0 | DL94: 0 | DM94: 0 | DN94: 601
B95: 208 | C95: Fédération Française de Ballon au Poing | D95: nr | E95: nr | F95: nr | G95: nr | H95: nr | I95: nr | J95: nr | K95: nr | L95: nr | M95: nr | N95: nr | O95: nr | P95: nr | Q95: nr | R95: nr | S95: nr | T95: nr | U95: nr | V95: nr | W95: nr | X95: nr | Y95: nr | Z95: nr | AA95: nr | AB95: nr | AC95: nr | AD95: nr | AE95: nr | AF95: nr | AG95: nr | AH95: nr | AI95: nr | AJ95: nr | AK95: nr | AL95: nr | AM95: nr | AN95: nr | AO95: nr | AP95: nr | AQ95: nr | AR95: nr | AS95: nr | AT95: nr | AU95: nr | AV95: nr | AW95: nr | AX95: nr | AY95: nr | AZ95: nr | BA95: nr | BB95: nr | BC95: nr | BD95: nr | BE95: nr | BF95: nr | BG95: nr | BH95: nr | BI95: nr | BJ95: nr | BK95: nr | BL95: nr | BM95: nr | BN95: nr | BO95: nr | BP95: nr | BQ95: nr | BR95: nr | BS95: nr | BT95: nr | BU95: nr | BV95: nr | BW95: nr | BX95: nr | BY95: nr | BZ95: nr | CA95: nr | CB95: nr | CC95: nr | CD95: nr | CE95: nr | CF95: nr | CG95: nr | CH95: nr | CI95: nr | CJ95: nr | CK95: nr | CL95: nr | CM95: nr | CN95: nr | CO95: nr | CP95: nr | CQ95: nr | CR95: nr | CS95: nr | CT95: nr | CU95: nr | CV95: nr | CW95: nr | CX95: nr | CY95: nr | CZ95: nr | DA95: nr | DB95: nr | DC95: nr | DD95: nr | DE95: nr | DF95: nr | DG95: nr | DH95: nr | DI95: nr | DJ95: nr | DK95: nr | DL95: nr | DM95: 542 | DN95: 542
B96: 234 | C96: Fédération Française Motonautique | D96: 17 | E96: 0 | F96: 2 | G96: 1 | H96: 0 | I96: 10 | J96: 2 | K96: 2 | L96: 0 | M96: 9 | N96: 8 | O96: 2 | P96: 31 | Q96: 5 | R96: 0 | S96: 1 | T96: 11 | U96: 1 | V96: 0 | W96: 4 | X96: 0 | Y96: 0 | Z96: 0 | AA96: 2 | AB96: 1 | AC96: 32 | AD96: 1 | AE96: 0 | AF96: 12 | AG96: 36 | AH96: 8 | AI96: 16 | AJ96: 1 | AK96: 20 | AL96: 4 | AM96: 3 | AN96: 0 | AO96: 1 | AP96: 4 | AQ96: 3 | AR96: 6 | AS96: 4 | AT96: 0 | AU96: 0 | AV96: 7 | AW96: 2 | AX96: 0 | AY96: 2 | AZ96: 0 | BA96: 16 | BB96: 4 | BC96: 0 | BD96: 1 | BE96: 2 | BF96: 1 | BG96: 1 | BH96: 4 | BI96: 1 | BJ96: 0 | BK96: 2 | BL96: 2 | BM96: 0 | BN96: 3 | BO96: 1 | BP96: 1 | BQ96: 0 | BR96: 5 | BS96: 1 | BT96: 0 | BU96: 8 | BV96: 0 | BW96: 6 | BX96: 0 | BY96: 4 | BZ96: 5 | CA96: 5 | CB96: 66 | CC96: 18 | CD96: 15 | CE96: 0 | CF96: 1 | CG96: 1 | CH96: 1 | CI96: 14 | CJ96: 1 | CK96: 0 | CL96: 0 | CM96: 0 | CN96: 4 | CO96: 4 | CP96: 0 | CQ96: 6 | CR96: 6 | CS96: 0 | CT96: 9 | CU96: 11 | CV96: 501 | CW96: 11 | CX96: 2 | CY96: 0 | CZ96: 0 | DA96: 0 | DB96: 13 | DC96: 514 | DD96: 0 | DE96: 0 | DF96: 0 | DG96: 0 | DH96: 0 | DI96: 1 | DJ96: 1 | DK96: 2 | DL96: 6 | DM96: 0 | DN96: 523
B97: 244 | C97: Fédération Française de Pulka et Traineau à Chiens | D97: 3 | E97: 2 | F97: 7 | G97: 0 | H97: 0 | I97: 11 | J97: 1 | K97: 0 | L97: 0 | M97: 9 | N97: 1 | O97: 0 | P97: 1 | Q97: 2 | R97: 0 | S97: 2 | T97: 1 | U97: 0 | V97: 2 | W97: 7 | X97: 0 | Y97: 0 | Z97: 0 | AA97: 2 | AB97: 2 | AC97: 25 | AD97: 3 | AE97: 4 | AF97: 0 | AG97: 0 | AH97: 1 | AI97: 0 | AJ97: 0 | AK97: 0 | AL97: 6 | AM97: 14 | AN97: 1 | AO97: 4 | AP97: 31 | AQ97: 7 | AR97: 1 | AS97: 7 | AT97: 4 | AU97: 0 | AV97: 11 | AW97: 9 | AX97: 3 | AY97: 0 | AZ97: 0 | BA97: 2 | BB97: 1 | BC97: 12 | BD97: 0 | BE97: 1 | BF97: 2 | BG97: 0 | BH97: 2 | BI97: 8 | BJ97: 1 | BK97: 6 | BL97: 7 | BM97: 5 | BN97: 4 | BO97: 19 | BP97: 0 | BQ97: 0 | BR97: 0 | BS97: 2 | BT97: 18 | BU97: 0 | BV97: 3 | BW97: 1 | BX97: 0 | BY97: 7 | BZ97: 12 | CA97: 1 | CB97: 53 | CC97: 7 | CD97: 17 | CE97: 2 | CF97: 4 | CG97: 2 | CH97: 1 | CI97: 0 | CJ97: 0 | CK97: 2 | CL97: 3 | CM97: 3 | CN97: 12 | CO97: 11 | CP97: 0 | CQ97: 9 | CR97: 1 | CS97: 0 | CT97: 1 | CU97: 5 | CV97: 431 | CW97: 0 | CX97: 0 | CY97: 0 | CZ97: 0 | DA97: 0 | DB97: 0 | DC97: 431 | DD97: 0 | DE97: 0 | DF97: 0 | DG97: 0 | DH97: 0 | DI97: 0 | DJ97: 0 | DK97: 0 | DL97: 0 | DM97: 0 | DN97: 431
B98: 224 | C98: Fédération Française d’hélicoptère | D98: 5 | E98: 0 | F98: 1 | G98: 0 | H98: 1 | I98: 3 | J98: 1 | K98: 0 | L98: 1 | M98: 0 | N98: 1 | O98: 3 | P98: 2 | Q98: 0 | R98: 0 | S98: 0 | T98: 2 | U98: 0 | V98: 4 | W98: 2 | X98: 2 | Y98: 0 | Z98: 6 | AA98: 1 | AB98: 2 | AC98: 0 | AD98: 0 | AE98: 12 | AF98: 0 | AG98: 1 | AH98: 2 | AI98: 21 | AJ98: 3 | AK98: 1 | AL98: 3 | AM98: 2 | AN98: 0 | AO98: 2 | AP98: 10 | AQ98: 1 | AR98: 3 | AS98: 0 | AT98: 1 | AU98: 1 | AV98: 0 | AW98: 1 | AX98: 2 | AY98: 0 | AZ98: 0 | BA98: 1 | BB98: 0 | BC98: 1 | BD98: 0 | BE98: 0 | BF98: 1 | BG98: 0 | BH98: 0 | BI98: 1 | BJ98: 0 | BK98: 0 | BL98: 1 | BM98: 0 | BN98: 2 | BO98: 0 | BP98: 2 | BQ98: 0 | BR98: 1 | BS98: 8 | BT98: 5 | BU98: 41 | BV98: 0 | BW98: 1 | BX98: 0 | BY98: 11 | BZ98: 3 | CA98: 0 | CB98: 1 | CC98: 2 | CD98: 4 | CE98: 0 | CF98: 0 | CG98: 7 | CH98: 0 | CI98: 0 | CJ98: 1 | CK98: 0 | CL98: 0 | CM98: 1 | CN98: 0 | CO98: 0 | CP98: 0 | CQ98: 1 | CR98: 3 | CS98: 0 | CT98: 2 | CU98: 1 | CV98: 205 | CW98: 1 | CX98: 0 | CY98: 0 | CZ98: 4 | DA98: 0 | DB98: 5 | DC98: 210 | DD98: 0 | DE98: 0 | DF98: 0 | DG98: 0 | DH98: 0 | DI98: 0 | DJ98: 0 | DK98: 0 | DL98: 7 | DM98: 0 | DN98: 217
